Workbook

Sheet CAMPS18
A1: N° -2 | B1: STRUCTURE ORGANISATRICE DU CAMP | C1: RÉGION ou RÉGION DE RATTACHEMENT DE L'ORGANISATEUR | D1: CAMP DÉCLARÉ AU TITRE DE L'ACCUEIL DE SCOUTISME | E1: PRÉCISEZ LES GROUPES SUR LE CAMP DE REGROUPEMENT | F1: DATE DE DÉBUT DU CAMP | G1: DATE DE FIN DU CAMP | H1: EFFECTIFS PRÉVISIONNELS LUTINS | I1: EFFECTIFS PRÉVISIONNELS RESPONSABLE LUTINS | J1: EFFECTIFS PRÉVISIONNELS LOUVETEAUX | K1: EFFECTIFS PRÉVISIONNELS RESPONSABLE LOUVETEAUX | L1: EFFECTIFS PRÉVISIONNELS ÉCLAIREUSES- ÉCLAIREURS | M1: EFFECTIFS PRÉVISIONNELS RESPONSABLE ÉCLAIREUSES- ÉCLAIREURS | N1: EFFECTIFS PRÉVISIONNELS AINÉS | O1: EFFECTIFS PRÉVISIONNELS RESPONSABLE AINÉS | P1: EFFECTIFS PRÉVISIONNELS NOMADES | Q1: EFFECTIFS PRÉVISIONNELS AUTRES ENCADREMENTS | R1: TOTAL PART | S1: TOTAL ENCADREMENT | T1: TAUX ENCADREMENT | U1: TOTAL DE PARTICIPANTS | V1: Résultats Lutins | W1: Résultats Responsables Lutins | X1: Résultats LVX | Y1: Résultats Responsables LVX | Z1: Résultats Eclés | AA1: Résultats Responsables Eclés | AB1: Résultats Aînés | AC1: Résultats Responsables Aînés | AD1: JAE- NOMADES | AE1: Autres Encadrements | AF1: IMPLANTATION DU CAMP | AG1: LIEU DU CAMP EN France | AH1: SI LE CAMP EST Á L'ÉTRANGER PRÉCISÉ LE PAYS | AI1: SOUHAITE PARTICIPER Á VIS MON CAMP | AJ1: DÉNOMINATION ET ADRESSE PRÉCISE DU CAMP | AL1: NOM ET PRÉNOM DU DIRECTEUR | AM1: MAIL DU DIRECTEUR | AN1: TÉLÉPHONE DU DIRECTEUR | AO1: NOM ET PRÉNOM DE L'ORGANISATEUR | AP1: MOIS DU CAMP | AQ1: DPT DU LIEU DU CAMP | AR1: RÉGION OU PAYS D'ACCUEIL | AS1: TYPE | AT1: CUA: Aînés- CUE: éclés- CULO : louvettte.teau- CULI : Lutin.e.s - CG : camp de groupe- CR : camp régional- CRGUE : Camp de regroupement d'unité éclés -CRGUA : Camp de regroupement d'unité Ainés -CRGULO : Camp de regroupement d'unité Louveteaux -CRGULI : Camp de regroupement d'unité Lutins -CRG : Camp de regroupement -RO : Camp régional ouvert - CIG : camp inter groupes - SAM: séjours adaptés mineurs - SAA : séjours adaptés adultes - SOU : séjours ouverts | AU1: - A : < 20 - B : 21-50 - C : 51-80 - D > 80 | AV1: - TN : N étant le nombre du taux
A2: 1 | C2: Languedoc Roussillon | D2: Camp d'unité Ainés | F2: 43288 | G2: 43303 | H2: 0 | I2: 0 | J2: 0 | K2: 0 | L2: 0 | M2: 0 | N2: 13 | O2: 2 | P2: 0 | Q2: 0 | R2: =H2+J2+L2+N2+P2 -> 13 | S2: =I2+K2+M2+O2+Q2 -> 2 | T2: =S2/R2 -> 0.15384615 | U2: =R2+S2 -> 15 | AB2: 1 | AC2: -1 | AF2: Camp fixe sous tente sans appui en dur | AG2: Argelès | AH2: Sitges (Espagne) | AJ2: Camping le Roussillonnais : boulevard de la Mer 66702 ARGELÈS SUR MER Camping Sitges : Ctra KM 246a 38. 08870 SITGES (Espagne) | AK2: ITINERANT | AL2: LEBEGUE Christophe | AM2: lebeguech@numericable.fr | AN2: 614723786 | AO2: LARTIGUE Philippe | AP2: 07 | AR2: Midi Pyrénées | AS2: G | AT2: =IF(D2="Camp d'unité Ainés","CUA",IF(D2="camp d'unité éclés","CUE",IF(D2="Camp d'unité louveteaux","CULO",IF(D2="Camp d'unité lutins","CULI",IF(D2="Camp de groupe","CG",IF(D2="Camp régional","CR",IF(D2="Camp de regroupement","CGG",IF(D2="Camp de regroupement d'unité Ainés","CRGUA",IF(D2="Camp de regroupement d'unité éclés","CRGUE",IF(D2="Camp de regroupement d'unité louveteaux","CRGULO",IF(D2="Camp de regroupement d'unité lutins","CRGULI",IF(D2="Camp inter groupe","CIG",IF(D2="Séjours adaptés mineurs","SAM",IF(D2="Séjours adaptés adultes","SAA",IF(D2="Séjours ouverts","SOU",IF(D2="Camp régional ouvert","RO")))))))))))))))) -> CUA | AU2: =IF(R2<=20,"A",IF(AND(R2>=21,R2<=50),"B",IF(AND(R2>=51,R2<=80),"C",IF(R2>80,"D")))) -> A | AV2: T | AW2: =BV2/BW2 -> #DIV/0!
A3: 2 | B3: Auvergne | C3: Auvergne | D3: Camp de regroupement | E3: La Merlerie La Meute | F3: 43297 | G3: 43311 | H3: 7 | I3: 2 | J3: 6 | K3: 2 | L3: 0 | M3: 0 | N3: 0 | O3: 0 | P3: 0 | Q3: 0 | R3: =H3+J3+L3+N3+P3 -> 13 | S3: =I3+K3+M3+O3+Q3 -> 4 | T3: =S3/R3 -> 0.30769231 | U3: =R3+S3 -> 17 | V3: -13 | W3: -1 | X3: -14 | Y3: -1 | AF3: Camp fixe sous tente avec appui en dur | AG3: Viscomtat | AJ3: 63463 | AK3: CPN | AL3: BANDA Alexandre | AM3: alexandre.banda@outlook.com | AN3: 619857146 | AO3: CORBARA Alexis | AP3: 07 | AQ3: 63 | AR3: Auvergne | AS3: G | AT3: =IF(D3="Camp d'unité Ainés","CUA",IF(D3="camp d'unité éclés","CUE",IF(D3="Camp d'unité louveteaux","CULO",IF(D3="Camp d'unité lutins","CULI",IF(D3="Camp de groupe","CG",IF(D3="Camp régional","CR",IF(D3="Camp de regroupement","CGG",IF(D3="Camp de regroupement d'unité Ainés","CRGUA",IF(D3="Camp de regroupement d'unité éclés","CRGUE",IF(D3="Camp de regroupement d'unité louveteaux","CRGULO",IF(D3="Camp de regroupement d'unité lutins","CRGULI",IF(D3="Camp inter groupe","CIG",IF(D3="Séjours adaptés mineurs","SAM",IF(D3="Séjours adaptés adultes","SAA",IF(D3="Séjours ouverts","SOU",IF(D3="Camp régional ouvert","RO")))))))))))))))) -> CGG | AU3: =IF(R3<=20,"A",IF(AND(R3>=21,R3<=50),"B",IF(AND(R3>=51,R3<=80),"C",IF(R3>80,"D")))) -> A | AV3: T | AW3: =BV3/BW3 -> #DIV/0!
A4: 3 | B4: Vichy | C4: Auvergne | D4: Camp de groupe | F4: 43290 | G4: 43304 | H4: 0 | I4: 0 | J4: 12 | K4: 2 | L4: 16 | M4: 3 | N4: 0 | O4: 0 | P4: 0 | Q4: 2 | R4: =H4+J4+L4+N4+P4 -> 28 | S4: =I4+K4+M4+O4+Q4 -> 7 | T4: =S4/R4 -> 0.25 | U4: =R4+S4 -> 35 | V4: -10 | W4: -2 | X4: -6 | Y4: -1 | Z4: 16 | AA4: 3 | AF4: Camp fixe sous tente sans appui en dur | AG4: Parnay | AJ4: Edouard Pisani-Ferry Champ des Frênes, Château de Targés 49730 PARNAY | AK4: EXT | AL4: DELANNOIS Michel | AM4: husky046@gmail.com | AN4: 626644811 | AO4: DELANNOIS Michel | AP4: 07 | AQ4: 49 | AR4: Pays de la Loire | AS4: G | AT4: =IF(D4="Camp d'unité Ainés","CUA",IF(D4="camp d'unité éclés","CUE",IF(D4="Camp d'unité louveteaux","CULO",IF(D4="Camp d'unité lutins","CULI",IF(D4="Camp de groupe","CG",IF(D4="Camp régional","CR",IF(D4="Camp de regroupement","CGG",IF(D4="Camp de regroupement d'unité Ainés","CRGUA",IF(D4="Camp de regroupement d'unité éclés","CRGUE",IF(D4="Camp de regroupement d'unité louveteaux","CRGULO",IF(D4="Camp de regroupement d'unité lutins","CRGULI",IF(D4="Camp inter groupe","CIG",IF(D4="Séjours adaptés mineurs","SAM",IF(D4="Séjours adaptés adultes","SAA",IF(D4="Séjours ouverts","SOU",IF(D4="Camp régional ouvert","RO")))))))))))))))) -> CG | AU4: =IF(R4<=20,"A",IF(AND(R4>=21,R4<=50),"B",IF(AND(R4>=51,R4<=80),"C",IF(R4>80,"D")))) -> B | AV4: T | AW4: =BV4/BW4 -> #DIV/0!
A5: 4 | B5: Puy en Velay | C5: Auvergne | D5: Camp de regroupement d'unité Ainés | E5: Limoges Paris Est | F5: 43290 | G5: 43308 | H5: 0 | I5: 0 | J5: 0 | K5: 0 | L5: 0 | M5: 0 | N5: 19 | O5: 4 | P5: 0 | Q5: 0 | R5: =H5+J5+L5+N5+P5 -> 19 | S5: =I5+K5+M5+O5+Q5 -> 4 | T5: =S5/R5 -> 0.21052632 | U5: =R5+S5 -> 23 | AB5: -3 | AC5: -1 | AE5: -1 | AF5: Camp fixe avec appui en dur | AG5: Brousse le Château | AI5: Oui | AJ5: Les amis de St Cyrice 12480 BROUSSE LE CHÂTEAU | AK5: EXT | AL5: BLANCHARD Timothé | AM5: timothe__blanchard@hotmail.fr | AN5: 677762449 | AO5: CORBARA Alexis | AP5: 07 | AQ5: 12 | AR5: Midi Pyrénées | AS5: G | AT5: =IF(D5="Camp d'unité Ainés","CUA",IF(D5="camp d'unité éclés","CUE",IF(D5="Camp d'unité louveteaux","CULO",IF(D5="Camp d'unité lutins","CULI",IF(D5="Camp de groupe","CG",IF(D5="Camp régional","CR",IF(D5="Camp de regroupement","CGG",IF(D5="Camp de regroupement d'unité Ainés","CRGUA",IF(D5="Camp de regroupement d'unité éclés","CRGUE",IF(D5="Camp de regroupement d'unité louveteaux","CRGULO",IF(D5="Camp de regroupement d'unité lutins","CRGULI",IF(D5="Camp inter groupe","CIG",IF(D5="Séjours adaptés mineurs","SAM",IF(D5="Séjours adaptés adultes","SAA",IF(D5="Séjours ouverts","SOU",IF(D5="Camp régional ouvert","RO")))))))))))))))) -> CRGUA | AU5: =IF(R5<=20,"A",IF(AND(R5>=21,R5<=50),"B",IF(AND(R5>=51,R5<=80),"C",IF(R5>80,"D")))) -> A | AV5: T | AW5: =BV5/BW5 -> #DIV/0!
A6: 5 | B6: Cournon | C6: Auvergne | D6: Camp de groupe | F6: 43297 | G6: 43312 | H6: 0 | I6: 0 | J6: 19 | K6: 8 | L6: 22 | M6: 7 | N6: 0 | O6: 0 | P6: 0 | Q6: 4 | R6: =H6+J6+L6+N6+P6 -> 41 | S6: =I6+K6+M6+O6+Q6 -> 19 | T6: =S6/R6 -> 0.46341463 | U6: =R6+S6 -> 60 | X6: -1 | Y6: 3 | Z6: -3 | AA6: 2 | AF6: Camp fixe avec appui en dur | AG6: La Motte en Champsaur | AJ6: Centre EEDF Les Molines 05500 LA MOTTE EN CHAMPSAUR | AK6: LOCATION | AL6: SUDRE Lucille | AM6: lucilesudre63@gmail.com | AN6: 623799447 | AO6: AUDIER Marie Noëlle | AP6: 07 | AQ6: 05 | AR6: PACA | AS6: G | AT6: =IF(D6="Camp d'unité Ainés","CUA",IF(D6="camp d'unité éclés","CUE",IF(D6="Camp d'unité louveteaux","CULO",IF(D6="Camp d'unité lutins","CULI",IF(D6="Camp de groupe","CG",IF(D6="Camp régional","CR",IF(D6="Camp de regroupement","CGG",IF(D6="Camp de regroupement d'unité Ainés","CRGUA",IF(D6="Camp de regroupement d'unité éclés","CRGUE",IF(D6="Camp de regroupement d'unité louveteaux","CRGULO",IF(D6="Camp de regroupement d'unité lutins","CRGULI",IF(D6="Camp inter groupe","CIG",IF(D6="Séjours adaptés mineurs","SAM",IF(D6="Séjours adaptés adultes","SAA",IF(D6="Séjours ouverts","SOU",IF(D6="Camp régional ouvert","RO")))))))))))))))) -> CG | AU6: =IF(R6<=20,"A",IF(AND(R6>=21,R6<=50),"B",IF(AND(R6>=51,R6<=80),"C",IF(R6>80,"D")))) -> B | AV6: T | AW6: =BV6/BW6 -> #DIV/0!
A7: 6 | B7: Cournon | C7: Auvergne | D7: Camp d'unité Ainés | F7: 43292 | G7: 43313 | H7: 0 | I7: 0 | J7: 0 | K7: 0 | L7: 0 | M7: 0 | N7: 18 | O7: 4 | P7: 0 | Q7: 0 | R7: =H7+J7+L7+N7+P7 -> 18 | S7: =I7+K7+M7+O7+Q7 -> 4 | T7: =S7/R7 -> 0.22222222 | U7: =R7+S7 -> 22 | AB7: -1 | AF7: Camp fixe sous tente sans appui en dur | AH7: Madagascar | AJ7: Mamy RAKOTCHARINIVO 17 rue Stefani Amparibe BP 1415 ANATLAKELY-101 ANTANANARIVO MADAGASCAR | AK7: ETRANGER | AL7: BISSON Odeline | AM7: odelinebisson@hotmail.com | AN7: 637828714 | AO7: AUDIER Marie Noëlle | AP7: 07/08 | AS7: G | AT7: =IF(D7="Camp d'unité Ainés","CUA",IF(D7="camp d'unité éclés","CUE",IF(D7="Camp d'unité louveteaux","CULO",IF(D7="Camp d'unité lutins","CULI",IF(D7="Camp de groupe","CG",IF(D7="Camp régional","CR",IF(D7="Camp de regroupement","CGG",IF(D7="Camp de regroupement d'unité Ainés","CRGUA",IF(D7="Camp de regroupement d'unité éclés","CRGUE",IF(D7="Camp de regroupement d'unité louveteaux","CRGULO",IF(D7="Camp de regroupement d'unité lutins","CRGULI",IF(D7="Camp inter groupe","CIG",IF(D7="Séjours adaptés mineurs","SAM",IF(D7="Séjours adaptés adultes","SAA",IF(D7="Séjours ouverts","SOU",IF(D7="Camp régional ouvert","RO")))))))))))))))) -> CUA | AU7: =IF(R7<=20,"A",IF(AND(R7>=21,R7<=50),"B",IF(AND(R7>=51,R7<=80),"C",IF(R7>80,"D")))) -> A | AV7: T | AW7: =BV7/BW7 -> #DIV/0!
A8: 7 | B8: Puy en Velay | C8: Auvergne | D8: Camp de regroupement | E8: Cassiopée | F8: 43291 | G8: 43311 | H8: 6 | I8: 2 | J8: 15 | K8: 4 | L8: 15 | M8: 6 | N8: 0 | O8: 0 | P8: 0 | Q8: 2 | R8: =H8+J8+L8+N8+P8 -> 36 | S8: =I8+K8+M8+O8+Q8 -> 14 | T8: =S8/R8 -> 0.38888889 | U8: =R8+S8 -> 50 | V8: -4 | X8: -5 | Y8: -1 | Z8: -5 | AA8: 1 | AE8: 1 | AF8: Camp fixe avec appui en dur | AG8: Montredon Labessonnie | AJ8: M. ou Mme Courtarel Bouisset La Borie Maigre 82360 MONTREDON LABESSONNIE | AK8: EXT | AL8: SANQUER Léo | AM8: leosanquer@laposte.net | AN8: 758251193 | AO8: CORBARA Alexis | AP8: 07 | AQ8: 82 | AR8: Midi Pyrénées | AS8: G | AT8: =IF(D8="Camp d'unité Ainés","CUA",IF(D8="camp d'unité éclés","CUE",IF(D8="Camp d'unité louveteaux","CULO",IF(D8="Camp d'unité lutins","CULI",IF(D8="Camp de groupe","CG",IF(D8="Camp régional","CR",IF(D8="Camp de regroupement","CGG",IF(D8="Camp de regroupement d'unité Ainés","CRGUA",IF(D8="Camp de regroupement d'unité éclés","CRGUE",IF(D8="Camp de regroupement d'unité louveteaux","CRGULO",IF(D8="Camp de regroupement d'unité lutins","CRGULI",IF(D8="Camp inter groupe","CIG",IF(D8="Séjours adaptés mineurs","SAM",IF(D8="Séjours adaptés adultes","SAA",IF(D8="Séjours ouverts","SOU",IF(D8="Camp régional ouvert","RO")))))))))))))))) -> CGG | AU8: =IF(R8<=20,"A",IF(AND(R8>=21,R8<=50),"B",IF(AND(R8>=51,R8<=80),"C",IF(R8>80,"D")))) -> B | AV8: T | AW8: =BV8/BW8 -> #DIV/0!
A9: 8 | B9: Royat Chamalière | C9: Auvergne | D9: Camp de groupe | F9: 43316 | G9: 43337 | H9: 2 | I9: 1 | J9: 5 | K9: 1 | L9: 8 | M9: 2 | N9: 0 | O9: 0 | P9: 0 | Q9: 2 | R9: =H9+J9+L9+N9+P9 -> 15 | S9: =I9+K9+M9+O9+Q9 -> 6 | T9: =S9/R9 -> 0.4 | U9: =R9+S9 -> 21 | V9: -1 | X9: -2 | Y9: -1 | Z9: -2 | AE9: 1 | AF9: Camp fixe avec appui en dur | AG9: Queaux | AJ9: 86203 | AK9: CENTRE | AL9: DENTIN Clémence | AM9: clemencedentin.klm@gmail.com | AN9: 07 82 86 20 92 | AO9: TRUCHASSOU Floriane | AP9: 08 | AQ9: 86 | AR9: Poitou Charente | AS9: G | AT9: =IF(D9="Camp d'unité Ainés","CUA",IF(D9="camp d'unité éclés","CUE",IF(D9="Camp d'unité louveteaux","CULO",IF(D9="Camp d'unité lutins","CULI",IF(D9="Camp de groupe","CG",IF(D9="Camp régional","CR",IF(D9="Camp de regroupement","CGG",IF(D9="Camp de regroupement d'unité Ainés","CRGUA",IF(D9="Camp de regroupement d'unité éclés","CRGUE",IF(D9="Camp de regroupement d'unité louveteaux","CRGULO",IF(D9="Camp de regroupement d'unité lutins","CRGULI",IF(D9="Camp inter groupe","CIG",IF(D9="Séjours adaptés mineurs","SAM",IF(D9="Séjours adaptés adultes","SAA",IF(D9="Séjours ouverts","SOU",IF(D9="Camp régional ouvert","RO")))))))))))))))) -> CG | AU9: =IF(R9<=20,"A",IF(AND(R9>=21,R9<=50),"B",IF(AND(R9>=51,R9<=80),"C",IF(R9>80,"D")))) -> A | AV9: T | AW9: =BV9/BW9 -> #DIV/0!
A10: 9 | B10: Loche Beaulieu | C10: Centre | D10: Camp de regroupement | E10: Ventoux | F10: 43290 | G10: 43308 | H10: 4 | I10: 1 | J10: 13 | K10: 4 | L10: 32 | M10: 4 | N10: 0 | O10: 0 | P10: 0 | Q10: 3 | R10: =H10+J10+L10+N10+P10 -> 49 | S10: =I10+K10+M10+O10+Q10 -> 12 | T10: =S10/R10 -> 0.24489796 | U10: =R10+S10 -> 61 | V10: -2 | W10: 0 | X10: -7 | Y10: 0 | Z10: 6 | AA10: 1 | AB10: 0 | AC10: 0 | AD10: 0 | AE10: 3 | AF10: Camp fixe sous tente sans appui en dur | AG10: Espinchal | AJ10: Mairie Espinchal 63850 ESPINCHAL | AK10: MAIRIE | AL10: DUBERNAY Christophe | AM10: christophe.dubernay@gmail.com | AN10: 611775004 | AO10: FOUSSIER Suzanne | AP10: 07 | AQ10: 63 | AR10: Auvergne | AS10: G | AT10: =IF(D10="Camp d'unité Ainés","CUA",IF(D10="camp d'unité éclés","CUE",IF(D10="Camp d'unité louveteaux","CULO",IF(D10="Camp d'unité lutins","CULI",IF(D10="Camp de groupe","CG",IF(D10="Camp régional","CR",IF(D10="Camp de regroupement","CGG",IF(D10="Camp de regroupement d'unité Ainés","CRGUA",IF(D10="Camp de regroupement d'unité éclés","CRGUE",IF(D10="Camp de regroupement d'unité louveteaux","CRGULO",IF(D10="Camp de regroupement d'unité lutins","CRGULI",IF(D10="Camp inter groupe","CIG",IF(D10="Séjours adaptés mineurs","SAM",IF(D10="Séjours adaptés adultes","SAA",IF(D10="Séjours ouverts","SOU",IF(D10="Camp régional ouvert","RO")))))))))))))))) -> CGG | AU10: =IF(R10<=20,"A",IF(AND(R10>=21,R10<=50),"B",IF(AND(R10>=51,R10<=80),"C",IF(R10>80,"D")))) -> B | AV10: T | AW10: =BV10/BW10 -> #DIV/0!
A11: 10 | B11: Hellemmes | C11: Hauts de France | D11: Camp de groupe | F11: 43290 | G11: 43303 | H11: 5 | I11: 2 | J11: 14 | K11: 4 | L11: 10 | M11: 3 | N11: 0 | O11: 0 | P11: 0 | Q11: 2 | R11: =H11+J11+L11+N11+P11 -> 29 | S11: =I11+K11+M11+O11+Q11 -> 11 | T11: =S11/R11 -> 0.37931034 | U11: =R11+S11 -> 40 | V11: -1 | X11: -1 | Z11: -3 | AF11: Camp fixe sous tente sans appui en dur | AG11: Luzy | AJ11: Château de Chijy 58170 LUZY | AK11: EXT | AL11: DECHERF Caroline | AM11: caroline.decherf@gmail.com | AN11: 788218134 | AO11: HELEVAUT Cathy | AP11: 07 | AQ11: 58 | AR11: Bourgogne | AS11: G | AT11: =IF(D11="Camp d'unité Ainés","CUA",IF(D11="camp d'unité éclés","CUE",IF(D11="Camp d'unité louveteaux","CULO",IF(D11="Camp d'unité lutins","CULI",IF(D11="Camp de groupe","CG",IF(D11="Camp régional","CR",IF(D11="Camp de regroupement","CGG",IF(D11="Camp de regroupement d'unité Ainés","CRGUA",IF(D11="Camp de regroupement d'unité éclés","CRGUE",IF(D11="Camp de regroupement d'unité louveteaux","CRGULO",IF(D11="Camp de regroupement d'unité lutins","CRGULI",IF(D11="Camp inter groupe","CIG",IF(D11="Séjours adaptés mineurs","SAM",IF(D11="Séjours adaptés adultes","SAA",IF(D11="Séjours ouverts","SOU",IF(D11="Camp régional ouvert","RO")))))))))))))))) -> CG | AU11: =IF(R11<=20,"A",IF(AND(R11>=21,R11<=50),"B",IF(AND(R11>=51,R11<=80),"C",IF(R11>80,"D")))) -> B | AV11: T | AW11: =BV11/BW11 -> #DIV/0!
A12: 11 | B12: Gravelines | C12: Hauts de France | D12: Camp de groupe | F12: 43317 | G12: 43331 | H12: 0 | I12: 0 | J12: 0 | K12: 0 | L12: 19 | M12: 3 | N12: 7 | O12: 1 | P12: 0 | Q12: 0 | R12: =H12+J12+L12+N12+P12 -> 26 | S12: =I12+K12+M12+O12+Q12 -> 4 | T12: =S12/R12 -> 0.15384615 | U12: =R12+S12 -> 30 | Z12: -4 | AA12: 1 | AB12: 2 | AF12: Camp fixe sous tente sans appui en dur | AG12: Fontaine en Bray | AJ12: Association ICART ferme pédagogique 167 rue du Bourg 76440 FONTAINE EN BRAY | AK12: FERME | AL12: HELEVAUT Cathy | AM12: cathy.helevaut@gmail.com | AN12: 680709339 | AO12: HELEVAUT Cathy | AP12: 08 | AQ12: 76 | AR12: Normandie | AS12: G | AT12: =IF(D12="Camp d'unité Ainés","CUA",IF(D12="camp d'unité éclés","CUE",IF(D12="Camp d'unité louveteaux","CULO",IF(D12="Camp d'unité lutins","CULI",IF(D12="Camp de groupe","CG",IF(D12="Camp régional","CR",IF(D12="Camp de regroupement","CGG",IF(D12="Camp de regroupement d'unité Ainés","CRGUA",IF(D12="Camp de regroupement d'unité éclés","CRGUE",IF(D12="Camp de regroupement d'unité louveteaux","CRGULO",IF(D12="Camp de regroupement d'unité lutins","CRGULI",IF(D12="Camp inter groupe","CIG",IF(D12="Séjours adaptés mineurs","SAM",IF(D12="Séjours adaptés adultes","SAA",IF(D12="Séjours ouverts","SOU",IF(D12="Camp régional ouvert","RO")))))))))))))))) -> CG | AU12: =IF(R12<=20,"A",IF(AND(R12>=21,R12<=50),"B",IF(AND(R12>=51,R12<=80),"C",IF(R12>80,"D")))) -> B | AV12: T | AW12: =BV12/BW12 -> #DIV/0!
A13: 12 | B13: Lille 3 | C13: Hauts de France | D13: Camp de groupe | F13: 43289 | G13: 43303 | H13: 10 | I13: 2 | J13: 16 | K13: 4 | L13: 20 | M13: 3 | N13: 0 | O13: 0 | P13: 0 | Q13: 3 | R13: =H13+J13+L13+N13+P13 -> 46 | S13: =I13+K13+M13+O13+Q13 -> 12 | T13: =S13/R13 -> 0.26086957 | U13: =R13+S13 -> 58 | W13: -1 | X13: 1 | Y13: 1 | AF13: Camp fixe sous tente sans appui en dur | AG13: Plumelec | AJ13: Eva Bonnel Le Guer 56420 PLUMELEC | AK13: EXT | AL13: DERACHE Adrien | AM13: adrien@derache.eu | AN13: 636804514 | AO13: HELEVAUT Cathy | AP13: 07 | AQ13: 56 | AR13: Bretagne | AS13: G | AT13: =IF(D13="Camp d'unité Ainés","CUA",IF(D13="camp d'unité éclés","CUE",IF(D13="Camp d'unité louveteaux","CULO",IF(D13="Camp d'unité lutins","CULI",IF(D13="Camp de groupe","CG",IF(D13="Camp régional","CR",IF(D13="Camp de regroupement","CGG",IF(D13="Camp de regroupement d'unité Ainés","CRGUA",IF(D13="Camp de regroupement d'unité éclés","CRGUE",IF(D13="Camp de regroupement d'unité louveteaux","CRGULO",IF(D13="Camp de regroupement d'unité lutins","CRGULI",IF(D13="Camp inter groupe","CIG",IF(D13="Séjours adaptés mineurs","SAM",IF(D13="Séjours adaptés adultes","SAA",IF(D13="Séjours ouverts","SOU",IF(D13="Camp régional ouvert","RO")))))))))))))))) -> CG | AU13: =IF(R13<=20,"A",IF(AND(R13>=21,R13<=50),"B",IF(AND(R13>=51,R13<=80),"C",IF(R13>80,"D")))) -> B | AV13: T | AW13: =BV13/BW13 -> #DIV/0!
A14: 13 | B14: Villeneuve d'Ascq | C14: Hauts de France | D14: Camp d'unité Ainés | F14: 43316 | G14: 43332 | H14: 0 | I14: 0 | J14: 0 | K14: 0 | L14: 0 | M14: 0 | N14: 12 | O14: 2 | P14: 0 | Q14: 2 | R14: =H14+J14+L14+N14+P14 -> 12 | S14: =I14+K14+M14+O14+Q14 -> 4 | T14: =S14/R14 -> 0.33333333 | U14: =R14+S14 -> 16 | AF14: Itinérant | AG14: Bécours | AH14: République Tchèque | AJ14: 12131 | AK14: CPN | AL14: EWALD Eliot | AM14: eliot.ewald@gmail.com | AN14: 621291640 | AO14: HELEVAUT Cathy | AP14: 08 | AR14: _ | AS14: G | AT14: =IF(D14="Camp d'unité Ainés","CUA",IF(D14="camp d'unité éclés","CUE",IF(D14="Camp d'unité louveteaux","CULO",IF(D14="Camp d'unité lutins","CULI",IF(D14="Camp de groupe","CG",IF(D14="Camp régional","CR",IF(D14="Camp de regroupement","CGG",IF(D14="Camp de regroupement d'unité Ainés","CRGUA",IF(D14="Camp de regroupement d'unité éclés","CRGUE",IF(D14="Camp de regroupement d'unité louveteaux","CRGULO",IF(D14="Camp de regroupement d'unité lutins","CRGULI",IF(D14="Camp inter groupe","CIG",IF(D14="Séjours adaptés mineurs","SAM",IF(D14="Séjours adaptés adultes","SAA",IF(D14="Séjours ouverts","SOU",IF(D14="Camp régional ouvert","RO")))))))))))))))) -> CUA | AU14: =IF(R14<=20,"A",IF(AND(R14>=21,R14<=50),"B",IF(AND(R14>=51,R14<=80),"C",IF(R14>80,"D")))) -> A | AV14: T | AW14: =BV14/BW14 -> #DIV/0!
A15: 14 | B15: Gravelines | C15: Hauts de France | D15: Camp de groupe | F15: 43317 | G15: 43331 | H15: 3 | I15: 0 | J15: 11 | K15: 2 | L15: 0 | M15: 0 | N15: 0 | O15: 0 | P15: 0 | Q15: 1 | R15: =H15+J15+L15+N15+P15 -> 14 | S15: =I15+K15+M15+O15+Q15 -> 3 | T15: =S15/R15 -> 0.21428571 | U15: =R15+S15 -> 17 | V15: -1 | AF15: Camp fixe sous tente sans appui en dur | AG15: Fontaine en Bray | AJ15: Association ICART ferme pédagogique 167 rue du Bourg 76440 FONTAINE EN BRAY | AK15: FERME | AL15: MAXIMY Sandrine | AM15: sandrine.srine@gmail.com | AN15: 630550147 | AO15: HELEVAUT Cathy | AP15: 08 | AQ15: 76 | AR15: Normandie | AS15: G | AT15: =IF(D15="Camp d'unité Ainés","CUA",IF(D15="camp d'unité éclés","CUE",IF(D15="Camp d'unité louveteaux","CULO",IF(D15="Camp d'unité lutins","CULI",IF(D15="Camp de groupe","CG",IF(D15="Camp régional","CR",IF(D15="Camp de regroupement","CGG",IF(D15="Camp de regroupement d'unité Ainés","CRGUA",IF(D15="Camp de regroupement d'unité éclés","CRGUE",IF(D15="Camp de regroupement d'unité louveteaux","CRGULO",IF(D15="Camp de regroupement d'unité lutins","CRGULI",IF(D15="Camp inter groupe","CIG",IF(D15="Séjours adaptés mineurs","SAM",IF(D15="Séjours adaptés adultes","SAA",IF(D15="Séjours ouverts","SOU",IF(D15="Camp régional ouvert","RO")))))))))))))))) -> CG | AU15: =IF(R15<=20,"A",IF(AND(R15>=21,R15<=50),"B",IF(AND(R15>=51,R15<=80),"C",IF(R15>80,"D")))) -> A | AV15: T | AW15: =BV15/BW15 -> #DIV/0!
A16: 15 | B16: Villeneuve d'Ascq | C16: Hauts de France | D16: Camp de regroupement | E16: Hazebrouck | F16: 43292 | G16: 43308 | H16: 3 | I16: 1 | J16: 24 | K16: 6 | L16: 25 | M16: 7 | N16: 10 | O16: 3 | P16: 0 | Q16: 3 | R16: =H16+J16+L16+N16+P16 -> 62 | S16: =I16+K16+M16+O16+Q16 -> 20 | T16: =S16/R16 -> 0.32258065 | U16: =R16+S16 -> 82 | X16: 7 | AF16: Camp fixe sous tente sans appui en dur | AG16: Ferrière sur Beaulieu | AI16: Oui | AJ16: 37132 | AK16: CENTRE | AL16: DUMORTIER WOLF Lucie | AM16: secretaire.eedfjulesverne@gmail.com | AN16: 608709956 | AO16: RINGOT Victor | AP16: 07 | AQ16: 37 | AR16: Centre | AS16: G | AT16: =IF(D16="Camp d'unité Ainés","CUA",IF(D16="camp d'unité éclés","CUE",IF(D16="Camp d'unité louveteaux","CULO",IF(D16="Camp d'unité lutins","CULI",IF(D16="Camp de groupe","CG",IF(D16="Camp régional","CR",IF(D16="Camp de regroupement","CGG",IF(D16="Camp de regroupement d'unité Ainés","CRGUA",IF(D16="Camp de regroupement d'unité éclés","CRGUE",IF(D16="Camp de regroupement d'unité louveteaux","CRGULO",IF(D16="Camp de regroupement d'unité lutins","CRGULI",IF(D16="Camp inter groupe","CIG",IF(D16="Séjours adaptés mineurs","SAM",IF(D16="Séjours adaptés adultes","SAA",IF(D16="Séjours ouverts","SOU",IF(D16="Camp régional ouvert","RO")))))))))))))))) -> CGG | AU16: =IF(R16<=20,"A",IF(AND(R16>=21,R16<=50),"B",IF(AND(R16>=51,R16<=80),"C",IF(R16>80,"D")))) -> C | AV16: T | AW16: =BV16/BW16 -> #DIV/0!
A17: 16 | B17: Centre de Morbecque | C17: Hauts de France | D17: Camp de regroupement d'unité éclés | E17: Croque vacances | F17: 43311 | G17: 43324 | H17: 0 | I17: 0 | J17: 0 | K17: 0 | L17: 40 | M17: 6 | N17: 0 | O17: 0 | P17: 0 | Q17: 0 | R17: =H17+J17+L17+N17+P17 -> 40 | S17: =I17+K17+M17+O17+Q17 -> 6 | T17: =S17/R17 -> 0.15 | U17: =R17+S17 -> 46 | AF17: Camp fixe sous tente avec appui en dur | AG17: Morbecque | AJ17: 59416 | AK17: CPN | AL17: DECONINCK Jordan | AM17: deconinck.jordan@gmail.com | AN17: 645824037 | AO17: HELEVAUT Cathy | AP17: 07/08 | AQ17: 59 | AR17: Hauts de france | AS17: C | AT17: =IF(D17="Camp d'unité Ainés","CUA",IF(D17="camp d'unité éclés","CUE",IF(D17="Camp d'unité louveteaux","CULO",IF(D17="Camp d'unité lutins","CULI",IF(D17="Camp de groupe","CG",IF(D17="Camp régional","CR",IF(D17="Camp de regroupement","CGG",IF(D17="Camp de regroupement d'unité Ainés","CRGUA",IF(D17="Camp de regroupement d'unité éclés","CRGUE",IF(D17="Camp de regroupement d'unité louveteaux","CRGULO",IF(D17="Camp de regroupement d'unité lutins","CRGULI",IF(D17="Camp inter groupe","CIG",IF(D17="Séjours adaptés mineurs","SAM",IF(D17="Séjours adaptés adultes","SAA",IF(D17="Séjours ouverts","SOU",IF(D17="Camp régional ouvert","RO")))))))))))))))) -> CRGUE | AU17: =IF(R17<=20,"A",IF(AND(R17>=21,R17<=50),"B",IF(AND(R17>=51,R17<=80),"C",IF(R17>80,"D")))) -> B | AV17: T | AW17: =BV17/BW17 -> #DIV/0!
A18: 17 | B18: Centre de Morbecque | C18: Hauts de France | D18: Camp de regroupement | E18: Croque vacances | F18: 43289 | G18: 43301 | H18: 0 | I18: 0 | J18: 20 | K18: 3 | L18: 20 | M18: 3 | N18: 20 | O18: 3 | P18: 0 | Q18: 0 | R18: =H18+J18+L18+N18+P18 -> 60 | S18: =I18+K18+M18+O18+Q18 -> 9 | T18: =S18/R18 -> 0.15 | U18: =R18+S18 -> 69 | AF18: Camp fixe sous tente avec appui en dur | AG18: Morbecque | AJ18: 59416 | AK18: CPN | AL18: DRUVENT Romain | AM18: romaindruvent@gmail.com | AN18: 659201183 | AO18: HELEVAUT Cathy | AP18: 07 | AQ18: 59 | AR18: Hauts de france | AS18: C | AT18: =IF(D18="Camp d'unité Ainés","CUA",IF(D18="camp d'unité éclés","CUE",IF(D18="Camp d'unité louveteaux","CULO",IF(D18="Camp d'unité lutins","CULI",IF(D18="Camp de groupe","CG",IF(D18="Camp régional","CR",IF(D18="Camp de regroupement","CGG",IF(D18="Camp de regroupement d'unité Ainés","CRGUA",IF(D18="Camp de regroupement d'unité éclés","CRGUE",IF(D18="Camp de regroupement d'unité louveteaux","CRGULO",IF(D18="Camp de regroupement d'unité lutins","CRGULI",IF(D18="Camp inter groupe","CIG",IF(D18="Séjours adaptés mineurs","SAM",IF(D18="Séjours adaptés adultes","SAA",IF(D18="Séjours ouverts","SOU",IF(D18="Camp régional ouvert","RO")))))))))))))))) -> CGG | AU18: =IF(R18<=20,"A",IF(AND(R18>=21,R18<=50),"B",IF(AND(R18>=51,R18<=80),"C",IF(R18>80,"D")))) -> C | AV18: T | AW18: =BV18/BW18 -> #DIV/0!
A19: 18 | B19: Centre de Morbecque | C19: Hauts de France | D19: Camp de regroupement | E19: Croque vacances | F19: 43289 | G19: 43294 | H19: 20 | I19: 3 | J19: 20 | K19: 3 | L19: 0 | M19: 0 | N19: 0 | O19: 0 | P19: 0 | Q19: 0 | R19: =H19+J19+L19+N19+P19 -> 40 | S19: =I19+K19+M19+O19+Q19 -> 6 | T19: =S19/R19 -> 0.15 | U19: =R19+S19 -> 46 | AF19: Camp fixe sous tente avec appui en dur | AG19: Morbecque | AJ19: 59416 | AK19: CPN | AL19: ENGLOO Aurélie | AM19: aurelie.engloo@gmail.com | AN19: 633819880 | AO19: HELEVAUT Cathy | AP19: 07 | AQ19: 59 | AR19: Hauts de france | AS19: C | AT19: =IF(D19="Camp d'unité Ainés","CUA",IF(D19="camp d'unité éclés","CUE",IF(D19="Camp d'unité louveteaux","CULO",IF(D19="Camp d'unité lutins","CULI",IF(D19="Camp de groupe","CG",IF(D19="Camp régional","CR",IF(D19="Camp de regroupement","CGG",IF(D19="Camp de regroupement d'unité Ainés","CRGUA",IF(D19="Camp de regroupement d'unité éclés","CRGUE",IF(D19="Camp de regroupement d'unité louveteaux","CRGULO",IF(D19="Camp de regroupement d'unité lutins","CRGULI",IF(D19="Camp inter groupe","CIG",IF(D19="Séjours adaptés mineurs","SAM",IF(D19="Séjours adaptés adultes","SAA",IF(D19="Séjours ouverts","SOU",IF(D19="Camp régional ouvert","RO")))))))))))))))) -> CGG | AU19: =IF(R19<=20,"A",IF(AND(R19>=21,R19<=50),"B",IF(AND(R19>=51,R19<=80),"C",IF(R19>80,"D")))) -> B | AV19: T | AW19: =BV19/BW19 -> #DIV/0!
A20: 19 | B20: Centre de Morbecque | C20: Hauts de France | D20: Camp de regroupement | E20: Croque vacances | F20: 43309 | G20: 43315 | H20: 0 | I20: 0 | J20: 20 | K20: 3 | L20: 20 | M20: 3 | N20: 0 | O20: 0 | P20: 0 | Q20: 0 | R20: =H20+J20+L20+N20+P20 -> 40 | S20: =I20+K20+M20+O20+Q20 -> 6 | T20: =S20/R20 -> 0.15 | U20: =R20+S20 -> 46 | AF20: Camp fixe sous tente avec appui en dur | AG20: Morbecque | AJ20: 59416 | AK20: CPN | AL20: LATRECH Rachel | AM20: latrech.rachel@gmail.com | AN20: 769355118 | AO20: HELEVAUT Cathy | AP20: 07/08 | AQ20: 59 | AR20: Hauts de france | AS20: C | AT20: =IF(D20="Camp d'unité Ainés","CUA",IF(D20="camp d'unité éclés","CUE",IF(D20="Camp d'unité louveteaux","CULO",IF(D20="Camp d'unité lutins","CULI",IF(D20="Camp de groupe","CG",IF(D20="Camp régional","CR",IF(D20="Camp de regroupement","CGG",IF(D20="Camp de regroupement d'unité Ainés","CRGUA",IF(D20="Camp de regroupement d'unité éclés","CRGUE",IF(D20="Camp de regroupement d'unité louveteaux","CRGULO",IF(D20="Camp de regroupement d'unité lutins","CRGULI",IF(D20="Camp inter groupe","CIG",IF(D20="Séjours adaptés mineurs","SAM",IF(D20="Séjours adaptés adultes","SAA",IF(D20="Séjours ouverts","SOU",IF(D20="Camp régional ouvert","RO")))))))))))))))) -> CGG | AU20: =IF(R20<=20,"A",IF(AND(R20>=21,R20<=50),"B",IF(AND(R20>=51,R20<=80),"C",IF(R20>80,"D")))) -> B | AV20: T | AW20: =BV20/BW20 -> #DIV/0!
A21: 20 | B21: Loon Plage | C21: Hauts de France | D21: Camp de groupe | F21: 43290 | G21: 43308 | H21: 10 | I21: 2 | J21: 25 | K21: 5 | L21: 10 | M21: 2 | N21: 8 | O21: 1 | P21: 5 | Q21: 15 | R21: =H21+J21+L21+N21+P21 -> 58 | S21: =I21+K21+M21+O21+Q21 -> 25 | T21: =S21/R21 -> 0.43103448 | U21: =R21+S21 -> 83 | V21: 10 | W21: 2 | X21: 1 | Y21: 2 | AB21: 2 | AD21: 5 | AE21: 7 | AF21: Camp fixe sous tente avec appui en dur | AG21: Aragnouet | AJ21: 65017 | AK21: CPNB | AL21: HOGARD Christian | AM21: ch-hogard@hotmail.com | AN21: 603972759 | AO21: HOGART Christian | AP21: 07 | AQ21: 65 | AR21: Midi Pyrénées | AS21: G | AT21: =IF(D21="Camp d'unité Ainés","CUA",IF(D21="camp d'unité éclés","CUE",IF(D21="Camp d'unité louveteaux","CULO",IF(D21="Camp d'unité lutins","CULI",IF(D21="Camp de groupe","CG",IF(D21="Camp régional","CR",IF(D21="Camp de regroupement","CGG",IF(D21="Camp de regroupement d'unité Ainés","CRGUA",IF(D21="Camp de regroupement d'unité éclés","CRGUE",IF(D21="Camp de regroupement d'unité louveteaux","CRGULO",IF(D21="Camp de regroupement d'unité lutins","CRGULI",IF(D21="Camp inter groupe","CIG",IF(D21="Séjours adaptés mineurs","SAM",IF(D21="Séjours adaptés adultes","SAA",IF(D21="Séjours ouverts","SOU",IF(D21="Camp régional ouvert","RO")))))))))))))))) -> CG | AU21: =IF(R21<=20,"A",IF(AND(R21>=21,R21<=50),"B",IF(AND(R21>=51,R21<=80),"C",IF(R21>80,"D")))) -> C | AV21: T | AW21: =BV21/BW21 -> #DIV/0!
A22: 21 | B22: Centre de Morbecque | C22: Hauts de France | D22: Camp de regroupement | E22: Croque vacances | F22: 43331 | G22: 43343 | H22: 0 | I22: 0 | J22: 20 | K22: 3 | L22: 20 | M22: 3 | N22: 20 | O22: 3 | P22: 0 | Q22: 0 | R22: =H22+J22+L22+N22+P22 -> 60 | S22: =I22+K22+M22+O22+Q22 -> 9 | T22: =S22/R22 -> 0.15 | U22: =R22+S22 -> 69 | AF22: Camp fixe sous tente avec appui en dur | AG22: Morbecque | AJ22: 59416 | AK22: CPN | AL22: LATRECH Rachel | AM22: latrech.rachel@gmail.com | AN22: 769355118 | AO22: HELEVAUT Cathy | AP22: 08 | AQ22: 59 | AR22: Hauts de france | AS22: C | AT22: =IF(D22="Camp d'unité Ainés","CUA",IF(D22="camp d'unité éclés","CUE",IF(D22="Camp d'unité louveteaux","CULO",IF(D22="Camp d'unité lutins","CULI",IF(D22="Camp de groupe","CG",IF(D22="Camp régional","CR",IF(D22="Camp de regroupement","CGG",IF(D22="Camp de regroupement d'unité Ainés","CRGUA",IF(D22="Camp de regroupement d'unité éclés","CRGUE",IF(D22="Camp de regroupement d'unité louveteaux","CRGULO",IF(D22="Camp de regroupement d'unité lutins","CRGULI",IF(D22="Camp inter groupe","CIG",IF(D22="Séjours adaptés mineurs","SAM",IF(D22="Séjours adaptés adultes","SAA",IF(D22="Séjours ouverts","SOU",IF(D22="Camp régional ouvert","RO")))))))))))))))) -> CGG | AU22: =IF(R22<=20,"A",IF(AND(R22>=21,R22<=50),"B",IF(AND(R22>=51,R22<=80),"C",IF(R22>80,"D")))) -> C | AV22: T | AW22: =BV22/BW22 -> #DIV/0!
A23: 22 | B23: Loon Plage | C23: Hauts de France | D23: Camp de groupe | F23: 43317 | G23: 43338 | H23: 8 | I23: 2 | J23: 50 | K23: 10 | L23: 80 | M23: 12 | N23: 60 | O23: 8 | P23: 15 | Q23: 55 | R23: =H23+J23+L23+N23+P23 -> 213 | S23: =I23+K23+M23+O23+Q23 -> 87 | T23: =S23/R23 -> 0.4084507 | U23: =R23+S23 -> 300 | V23: 8 | W23: 2 | X23: -30 | Y23: 10 | Z23: -90 | AA23: 12 | AB23: 60 | AC23: 8 | AD23: 15 | AE23: -25 | AF23: Camp fixe sous tente avec appui en dur | AG23: Gravelines | AJ23: Ferme Doulet Ville de Gravelines rue C. Leurette 59820 GRAVELINES | AK23: FERME | AL23: HOGARD Christian | AM23: ch-hogard@hotmail.com | AN23: 603972759 | AO23: HOGART Christian | AP23: 08 | AQ23: 59 | AR23: Hauts de france | AS23: G | AT23: =IF(D23="Camp d'unité Ainés","CUA",IF(D23="camp d'unité éclés","CUE",IF(D23="Camp d'unité louveteaux","CULO",IF(D23="Camp d'unité lutins","CULI",IF(D23="Camp de groupe","CG",IF(D23="Camp régional","CR",IF(D23="Camp de regroupement","CGG",IF(D23="Camp de regroupement d'unité Ainés","CRGUA",IF(D23="Camp de regroupement d'unité éclés","CRGUE",IF(D23="Camp de regroupement d'unité louveteaux","CRGULO",IF(D23="Camp de regroupement d'unité lutins","CRGULI",IF(D23="Camp inter groupe","CIG",IF(D23="Séjours adaptés mineurs","SAM",IF(D23="Séjours adaptés adultes","SAA",IF(D23="Séjours ouverts","SOU",IF(D23="Camp régional ouvert","RO")))))))))))))))) -> CG | AU23: =IF(R23<=20,"A",IF(AND(R23>=21,R23<=50),"B",IF(AND(R23>=51,R23<=80),"C",IF(R23>80,"D")))) -> D | AV23: T | AW23: =BV23/BW23 -> #DIV/0!
A24: 23 | B24: Lambersart | C24: Hauts de France | D24: Camp de groupe | F24: 43317 | G24: 43338 | H24: 14 | I24: 6 | J24: 18 | K24: 5 | L24: 18 | M24: 5 | N24: 3 | O24: 0 | P24: 0 | Q24: 7 | R24: =H24+J24+L24+N24+P24 -> 53 | S24: =I24+K24+M24+O24+Q24 -> 23 | T24: =S24/R24 -> 0.43396226 | U24: =R24+S24 -> 76 | V24: -1 | W24: 2 | X24: -2 | Y24: 1 | Z24: -2 | AA24: 1 | AB24: -3 | AE24: 1 | AF24: Camp fixe sous tente sans appui en dur | AG24: Mialet | AJ24: Jacqueline Verdailhan et M JC Bruhamer la Rouquette 30140 MIALET | AK24: EXT | AL24: FOUACHE Christophe | AM24: christophe-fouache@orange.fr | AN24: 621180044 | AO24: FOUACHE Christophe | AP24: 08 | AQ24: 30 | AR24: Languedoc Roussillon | AS24: G | AT24: =IF(D24="Camp d'unité Ainés","CUA",IF(D24="camp d'unité éclés","CUE",IF(D24="Camp d'unité louveteaux","CULO",IF(D24="Camp d'unité lutins","CULI",IF(D24="Camp de groupe","CG",IF(D24="Camp régional","CR",IF(D24="Camp de regroupement","CGG",IF(D24="Camp de regroupement d'unité Ainés","CRGUA",IF(D24="Camp de regroupement d'unité éclés","CRGUE",IF(D24="Camp de regroupement d'unité louveteaux","CRGULO",IF(D24="Camp de regroupement d'unité lutins","CRGULI",IF(D24="Camp inter groupe","CIG",IF(D24="Séjours adaptés mineurs","SAM",IF(D24="Séjours adaptés adultes","SAA",IF(D24="Séjours ouverts","SOU",IF(D24="Camp régional ouvert","RO")))))))))))))))) -> CG | AU24: =IF(R24<=20,"A",IF(AND(R24>=21,R24<=50),"B",IF(AND(R24>=51,R24<=80),"C",IF(R24>80,"D")))) -> C | AV24: T | AW24: =BV24/BW24 -> #DIV/0!
A25: 24 | B25: Bègles | C25: Nouvelle Aquitaine | D25: Camp d'unité louveteaux | F25: 43290 | G25: 43308 | H25: 0 | I25: 0 | J25: 29 | K25: 4 | L25: 0 | M25: 0 | N25: 0 | O25: 0 | P25: 0 | Q25: 4 | R25: =H25+J25+L25+N25+P25 -> 29 | S25: =I25+K25+M25+O25+Q25 -> 8 | T25: =S25/R25 -> 0.27586207 | U25: =R25+S25 -> 37 | X25: 11 | AE25: 2 | AF25: Camp fixe sous tente sans appui en dur | AG25: Eygurande et Gardedeuil | AJ25: Camil Lansmarie Bost du Loup 24700 EYGURANDE ET GARDEDEUIL | AK25: EXT | AL25: MILON Philippe | AM25: philippemilon@free.fr | AN25: 610911767 | AO25: MILON Philippe | AP25: 07 | AQ25: 24 | AR25: Nouvelle Aquitaine | AS25: G | AT25: =IF(D25="Camp d'unité Ainés","CUA",IF(D25="camp d'unité éclés","CUE",IF(D25="Camp d'unité louveteaux","CULO",IF(D25="Camp d'unité lutins","CULI",IF(D25="Camp de groupe","CG",IF(D25="Camp régional","CR",IF(D25="Camp de regroupement","CGG",IF(D25="Camp de regroupement d'unité Ainés","CRGUA",IF(D25="Camp de regroupement d'unité éclés","CRGUE",IF(D25="Camp de regroupement d'unité louveteaux","CRGULO",IF(D25="Camp de regroupement d'unité lutins","CRGULI",IF(D25="Camp inter groupe","CIG",IF(D25="Séjours adaptés mineurs","SAM",IF(D25="Séjours adaptés adultes","SAA",IF(D25="Séjours ouverts","SOU",IF(D25="Camp régional ouvert","RO")))))))))))))))) -> CULO | AU25: =IF(R25<=20,"A",IF(AND(R25>=21,R25<=50),"B",IF(AND(R25>=51,R25<=80),"C",IF(R25>80,"D")))) -> B | AV25: T | AW25: =BV25/BW25 -> #DIV/0!
A26: 25 | B26: Talence | C26: Nouvelle Aquitaine | D26: Camp de groupe | F26: 43288 | G26: 43308 | H26: 5 | I26: 1 | J26: 13 | K26: 2 | L26: 17 | M26: 3 | N26: 0 | O26: 0 | P26: 0 | Q26: 1 | R26: =H26+J26+L26+N26+P26 -> 35 | S26: =I26+K26+M26+O26+Q26 -> 7 | T26: =S26/R26 -> 0.2 | U26: =R26+S26 -> 42 | X26: 1 | Z26: 7 | AA26: 1 | AF26: Camp fixe sous tente sans appui en dur | AG26: Les Graulges | AJ26: Morvan Eric Malut 24340 LES GRAULGES | AK26: EXT | AL26: DESBRUNAIS Jean Baptiste | AM26: jean-baptiste.desbrunais@laposte.net | AN26: 672435799 | AO26: DESBRUNAIS Jean Baptiste | AP26: 07 | AQ26: 24 | AR26: Nouvelle Aquitaine | AS26: G | AT26: =IF(D26="Camp d'unité Ainés","CUA",IF(D26="camp d'unité éclés","CUE",IF(D26="Camp d'unité louveteaux","CULO",IF(D26="Camp d'unité lutins","CULI",IF(D26="Camp de groupe","CG",IF(D26="Camp régional","CR",IF(D26="Camp de regroupement","CGG",IF(D26="Camp de regroupement d'unité Ainés","CRGUA",IF(D26="Camp de regroupement d'unité éclés","CRGUE",IF(D26="Camp de regroupement d'unité louveteaux","CRGULO",IF(D26="Camp de regroupement d'unité lutins","CRGULI",IF(D26="Camp inter groupe","CIG",IF(D26="Séjours adaptés mineurs","SAM",IF(D26="Séjours adaptés adultes","SAA",IF(D26="Séjours ouverts","SOU",IF(D26="Camp régional ouvert","RO")))))))))))))))) -> CG | AU26: =IF(R26<=20,"A",IF(AND(R26>=21,R26<=50),"B",IF(AND(R26>=51,R26<=80),"C",IF(R26>80,"D")))) -> B | AV26: T | AW26: =BV26/BW26 -> #DIV/0!
A27: 26 | B27: Bordeaux V | C27: Nouvelle Aquitaine | D27: Camp de groupe | F27: 43288 | G27: 43296 | H27: 12 | I27: 2 | J27: 26 | K27: 4 | L27: 0 | M27: 0 | N27: 0 | O27: 0 | P27: 0 | Q27: 1 | R27: =H27+J27+L27+N27+P27 -> 38 | S27: =I27+K27+M27+O27+Q27 -> 7 | T27: =S27/R27 -> 0.18421053 | U27: =R27+S27 -> 45 | V27: 3 | X27: 4 | Y27: 1 | AF27: Camp fixe sous tente avec appui en dur | AG27: Rauzan | AJ27: 1 lieu dit de Taris Vignoble Goudichaud 33420 RAUZAN | AK27: EXT | AL27: DE LA JOUSSELINIERE Ronan | AM27: rdlj@sfr.fr | AN27: 688767916 | AO27: RUMEAU LARROUTUROU Isabelle | AP27: 07 | AQ27: 33 | AR27: Nouvelle Aquitaine | AS27: G | AT27: =IF(D27="Camp d'unité Ainés","CUA",IF(D27="camp d'unité éclés","CUE",IF(D27="Camp d'unité louveteaux","CULO",IF(D27="Camp d'unité lutins","CULI",IF(D27="Camp de groupe","CG",IF(D27="Camp régional","CR",IF(D27="Camp de regroupement","CGG",IF(D27="Camp de regroupement d'unité Ainés","CRGUA",IF(D27="Camp de regroupement d'unité éclés","CRGUE",IF(D27="Camp de regroupement d'unité louveteaux","CRGULO",IF(D27="Camp de regroupement d'unité lutins","CRGULI",IF(D27="Camp inter groupe","CIG",IF(D27="Séjours adaptés mineurs","SAM",IF(D27="Séjours adaptés adultes","SAA",IF(D27="Séjours ouverts","SOU",IF(D27="Camp régional ouvert","RO")))))))))))))))) -> CG | AU27: =IF(R27<=20,"A",IF(AND(R27>=21,R27<=50),"B",IF(AND(R27>=51,R27<=80),"C",IF(R27>80,"D")))) -> B | AV27: T | AW27: =BV27/BW27 -> #DIV/0!
A28: 27 | B28: Limoges | C28: Nouvelle Aquitaine | D28: Camp de regroupement | E28: Paris Nord Périgueux Muret Chelles | F28: 43290 | G28: 43308 | H28: 14 | I28: 5 | J28: 23 | K28: 9 | L28: 38 | M28: 9 | N28: 0 | O28: 0 | P28: 0 | Q28: 3 | R28: =H28+J28+L28+N28+P28 -> 75 | S28: =I28+K28+M28+O28+Q28 -> 26 | T28: =S28/R28 -> 0.34666667 | U28: =R28+S28 -> 101 | V28: -6 | W28: -2 | X28: -2 | Z28: 23 | AE28: 3 | AF28: Camp fixe sous tente avec appui en dur | AG28: Le Bugue | AJ28: 24183 | AK28: CENTRE | AL28: BLANCHER Nathan | AM28: pro.nathan.blancher@gmail.com | AN28: 632213905 | AO28: ALAIS François | AP28: 07 | AQ28: 24 | AR28: Nouvelle Aquitaine | AS28: G | AT28: =IF(D28="Camp d'unité Ainés","CUA",IF(D28="camp d'unité éclés","CUE",IF(D28="Camp d'unité louveteaux","CULO",IF(D28="Camp d'unité lutins","CULI",IF(D28="Camp de groupe","CG",IF(D28="Camp régional","CR",IF(D28="Camp de regroupement","CGG",IF(D28="Camp de regroupement d'unité Ainés","CRGUA",IF(D28="Camp de regroupement d'unité éclés","CRGUE",IF(D28="Camp de regroupement d'unité louveteaux","CRGULO",IF(D28="Camp de regroupement d'unité lutins","CRGULI",IF(D28="Camp inter groupe","CIG",IF(D28="Séjours adaptés mineurs","SAM",IF(D28="Séjours adaptés adultes","SAA",IF(D28="Séjours ouverts","SOU",IF(D28="Camp régional ouvert","RO")))))))))))))))) -> CGG | AU28: =IF(R28<=20,"A",IF(AND(R28>=21,R28<=50),"B",IF(AND(R28>=51,R28<=80),"C",IF(R28>80,"D")))) -> C | AV28: T | AW28: =BV28/BW28 -> #DIV/0!
A29: 28 | B29: Mérignac | C29: Nouvelle Aquitaine | D29: Camp de regroupement | E29: Pau Tarbes | F29: 43289 | G29: 43311 | H29: 0 | I29: 0 | J29: 17 | K29: 5 | L29: 0 | M29: 0 | N29: 5 | O29: 1 | P29: 0 | Q29: 1 | R29: =H29+J29+L29+N29+P29 -> 22 | S29: =I29+K29+M29+O29+Q29 -> 7 | T29: =S29/R29 -> 0.31818182 | U29: =R29+S29 -> 29 | X29: -8 | Y29: -1 | AB29: -1 | AE29: 1 | AF29: Camp fixe sous tente avec appui en dur | AG29: Jacou | AJ29: Scoutisme Français Domaine de Viviers 34830 JACOU | AK29: EXT | AL29: DASSONVILLE Tanguy | AM29: eedfmerignac@gmail.com | AN29: 646402237 | AO29: GARDILLOU Claire | AP29: 07 | AQ29: 34 | AR29: Languedoc Roussillon | AS29: G | AT29: =IF(D29="Camp d'unité Ainés","CUA",IF(D29="camp d'unité éclés","CUE",IF(D29="Camp d'unité louveteaux","CULO",IF(D29="Camp d'unité lutins","CULI",IF(D29="Camp de groupe","CG",IF(D29="Camp régional","CR",IF(D29="Camp de regroupement","CGG",IF(D29="Camp de regroupement d'unité Ainés","CRGUA",IF(D29="Camp de regroupement d'unité éclés","CRGUE",IF(D29="Camp de regroupement d'unité louveteaux","CRGULO",IF(D29="Camp de regroupement d'unité lutins","CRGULI",IF(D29="Camp inter groupe","CIG",IF(D29="Séjours adaptés mineurs","SAM",IF(D29="Séjours adaptés adultes","SAA",IF(D29="Séjours ouverts","SOU",IF(D29="Camp régional ouvert","RO")))))))))))))))) -> CGG | AU29: =IF(R29<=20,"A",IF(AND(R29>=21,R29<=50),"B",IF(AND(R29>=51,R29<=80),"C",IF(R29>80,"D")))) -> B | AV29: T | AW29: =BV29/BW29 -> #DIV/0!
A30: 29 | B30: Bègles | C30: Nouvelle Aquitaine | D30: Camp d'unité éclés | F30: 43304 | G30: 43308 | H30: 0 | I30: 0 | J30: 0 | K30: 0 | L30: 13 | M30: 3 | N30: 0 | O30: 0 | P30: 0 | Q30: 0 | R30: =H30+J30+L30+N30+P30 -> 13 | S30: =I30+K30+M30+O30+Q30 -> 3 | T30: =S30/R30 -> 0.23076923 | U30: =R30+S30 -> 16 | Z30: -3 | AF30: Itinérant | AJ30: Itinérants | AK30: ITINERANT | AL30: ROUSSELET Léa | AM30: lea@rfpa.com | AN30: 648141084 | AO30: MILON Philippe | AP30: 07 | AS30: G | AT30: =IF(D30="Camp d'unité Ainés","CUA",IF(D30="camp d'unité éclés","CUE",IF(D30="Camp d'unité louveteaux","CULO",IF(D30="Camp d'unité lutins","CULI",IF(D30="Camp de groupe","CG",IF(D30="Camp régional","CR",IF(D30="Camp de regroupement","CGG",IF(D30="Camp de regroupement d'unité Ainés","CRGUA",IF(D30="Camp de regroupement d'unité éclés","CRGUE",IF(D30="Camp de regroupement d'unité louveteaux","CRGULO",IF(D30="Camp de regroupement d'unité lutins","CRGULI",IF(D30="Camp inter groupe","CIG",IF(D30="Séjours adaptés mineurs","SAM",IF(D30="Séjours adaptés adultes","SAA",IF(D30="Séjours ouverts","SOU",IF(D30="Camp régional ouvert","RO")))))))))))))))) -> CUE | AU30: =IF(R30<=20,"A",IF(AND(R30>=21,R30<=50),"B",IF(AND(R30>=51,R30<=80),"C",IF(R30>80,"D")))) -> A | AV30: T | AW30: =BV30/BW30 -> #DIV/0!
A31: 30 | B31: Entre deux Mer | C31: Nouvelle Aquitaine | D31: Camp de groupe | F31: 43290 | G31: 43303 | H31: 18 | I31: 4 | J31: 16 | K31: 4 | L31: 0 | M31: 0 | N31: 0 | O31: 0 | P31: 0 | Q31: 5 | R31: =H31+J31+L31+N31+P31 -> 34 | S31: =I31+K31+M31+O31+Q31 -> 13 | T31: =S31/R31 -> 0.38235294 | U31: =R31+S31 -> 47 | V31: -2 | W31: 1 | X31: -4 | Y31: 1 | AE31: 5 | AF31: Camp fixe sous tente sans appui en dur | AG31: St Christophec de Double | AJ31: 26 lieu dit Chaux 33230 SAINT CHRISTOPHE DE DOUBLE | AK31: EXT | AL31: LUKOVIC Snéjana | AM31: snejana.lukovic@gmail.com | AN31: 663257305 | AO31: BONNEAU Charley Mathilde | AP31: 07 | AQ31: 33 | AR31: Nouvelle Aquitaine | AS31: G | AT31: =IF(D31="Camp d'unité Ainés","CUA",IF(D31="camp d'unité éclés","CUE",IF(D31="Camp d'unité louveteaux","CULO",IF(D31="Camp d'unité lutins","CULI",IF(D31="Camp de groupe","CG",IF(D31="Camp régional","CR",IF(D31="Camp de regroupement","CGG",IF(D31="Camp de regroupement d'unité Ainés","CRGUA",IF(D31="Camp de regroupement d'unité éclés","CRGUE",IF(D31="Camp de regroupement d'unité louveteaux","CRGULO",IF(D31="Camp de regroupement d'unité lutins","CRGULI",IF(D31="Camp inter groupe","CIG",IF(D31="Séjours adaptés mineurs","SAM",IF(D31="Séjours adaptés adultes","SAA",IF(D31="Séjours ouverts","SOU",IF(D31="Camp régional ouvert","RO")))))))))))))))) -> CG | AU31: =IF(R31<=20,"A",IF(AND(R31>=21,R31<=50),"B",IF(AND(R31>=51,R31<=80),"C",IF(R31>80,"D")))) -> B | AV31: T | AW31: =BV31/BW31 -> #DIV/0!
A32: 31 | B32: Pessac Cestas | C32: Nouvelle Aquitaine | D32: Camp de groupe | F32: 43291 | G32: 43312 | H32: 4 | I32: 1 | J32: 20 | K32: 3 | L32: 26 | M32: 3 | N32: 11 | O32: 1 | P32: 0 | Q32: 6 | R32: =H32+J32+L32+N32+P32 -> 61 | S32: =I32+K32+M32+O32+Q32 -> 14 | T32: =S32/R32 -> 0.2295082 | U32: =R32+S32 -> 75 | AA32: -1 | AF32: Itinérant | AH32: Italie | AJ32: Domaie Forestier de Randello à RAGUSA | AK32: ETRANGER | AL32: POLONI Alexandre | AM32: polonialexandre@yahoo.fr | AN32: 658581265 | AO32: POLONI Claudine | AP32: 07 | AS32: G | AT32: =IF(D32="Camp d'unité Ainés","CUA",IF(D32="camp d'unité éclés","CUE",IF(D32="Camp d'unité louveteaux","CULO",IF(D32="Camp d'unité lutins","CULI",IF(D32="Camp de groupe","CG",IF(D32="Camp régional","CR",IF(D32="Camp de regroupement","CGG",IF(D32="Camp de regroupement d'unité Ainés","CRGUA",IF(D32="Camp de regroupement d'unité éclés","CRGUE",IF(D32="Camp de regroupement d'unité louveteaux","CRGULO",IF(D32="Camp de regroupement d'unité lutins","CRGULI",IF(D32="Camp inter groupe","CIG",IF(D32="Séjours adaptés mineurs","SAM",IF(D32="Séjours adaptés adultes","SAA",IF(D32="Séjours ouverts","SOU",IF(D32="Camp régional ouvert","RO")))))))))))))))) -> CG | AU32: =IF(R32<=20,"A",IF(AND(R32>=21,R32<=50),"B",IF(AND(R32>=51,R32<=80),"C",IF(R32>80,"D")))) -> C | AV32: T | AW32: =BV32/BW32 -> #DIV/0!
A33: 32 | B33: Montredon Labessonnié | C33: Midi Pyrénées | D33: Camp d'unité éclés | F33: 43325 | G33: 43338 | H33: 0 | I33: 0 | J33: 0 | K33: 0 | L33: 9 | M33: 1 | N33: 0 | O33: 0 | P33: 0 | Q33: 0 | R33: =H33+J33+L33+N33+P33 -> 9 | S33: =I33+K33+M33+O33+Q33 -> 1 | T33: =S33/R33 -> 0.11111111 | U33: =R33+S33 -> 10 | Z33: 1 | AA33: -3 | AF33: Camp fixe sous tente avec appui en dur | AH33: Italie | AJ33: Association Légambienté Paestum, Pasquale Longo Legambienté Paestum Via Magna Graecia - Torre 27 (area archeologica) 84047 Capaccio Paestum | AK33: ETRANGER | AL33: MARQUES Mélanie | AM33: melanie.marques81@laposte.net | AN33: 633393908 | AO33: DUZES Christelle | AP33: 08 | AS33: G | AT33: =IF(D33="Camp d'unité Ainés","CUA",IF(D33="camp d'unité éclés","CUE",IF(D33="Camp d'unité louveteaux","CULO",IF(D33="Camp d'unité lutins","CULI",IF(D33="Camp de groupe","CG",IF(D33="Camp régional","CR",IF(D33="Camp de regroupement","CGG",IF(D33="Camp de regroupement d'unité Ainés","CRGUA",IF(D33="Camp de regroupement d'unité éclés","CRGUE",IF(D33="Camp de regroupement d'unité louveteaux","CRGULO",IF(D33="Camp de regroupement d'unité lutins","CRGULI",IF(D33="Camp inter groupe","CIG",IF(D33="Séjours adaptés mineurs","SAM",IF(D33="Séjours adaptés adultes","SAA",IF(D33="Séjours ouverts","SOU",IF(D33="Camp régional ouvert","RO")))))))))))))))) -> CUE | AU33: =IF(R33<=20,"A",IF(AND(R33>=21,R33<=50),"B",IF(AND(R33>=51,R33<=80),"C",IF(R33>80,"D")))) -> A | AV33: T | AW33: =BV33/BW33 -> #DIV/0!
A34: 33 | B34: Bordeaux V | C34: Nouvelle Aquitaine | D34: Camp d'unité éclés | F34: 43290 | G34: 43308 | H34: 0 | I34: 0 | J34: 0 | K34: 0 | L34: 29 | M34: 2 | N34: 0 | O34: 0 | P34: 0 | Q34: 0 | R34: =H34+J34+L34+N34+P34 -> 29 | S34: =I34+K34+M34+O34+Q34 -> 2 | T34: =S34/R34 -> 0.068965517 | U34: =R34+S34 -> 31 | Z34: -1 | AA34: -2 | AF34: Camp fixe sous tente avec appui en dur | AH34: Italie | AJ34: CNGEI SEDE Centrale Viale Di Val Fioita BRR0144 ROMA | AK34: ETRANGER | AL34: RUMEAU LARROUTUROU Isabelle | AM34: otarie.epervier@orange.fr | AN34: 670867791 | AO34: RUMEAU LARROUTUROU Isabelle | AP34: 07 | AS34: G | AT34: =IF(D34="Camp d'unité Ainés","CUA",IF(D34="camp d'unité éclés","CUE",IF(D34="Camp d'unité louveteaux","CULO",IF(D34="Camp d'unité lutins","CULI",IF(D34="Camp de groupe","CG",IF(D34="Camp régional","CR",IF(D34="Camp de regroupement","CGG",IF(D34="Camp de regroupement d'unité Ainés","CRGUA",IF(D34="Camp de regroupement d'unité éclés","CRGUE",IF(D34="Camp de regroupement d'unité louveteaux","CRGULO",IF(D34="Camp de regroupement d'unité lutins","CRGULI",IF(D34="Camp inter groupe","CIG",IF(D34="Séjours adaptés mineurs","SAM",IF(D34="Séjours adaptés adultes","SAA",IF(D34="Séjours ouverts","SOU",IF(D34="Camp régional ouvert","RO")))))))))))))))) -> CUE | AU34: =IF(R34<=20,"A",IF(AND(R34>=21,R34<=50),"B",IF(AND(R34>=51,R34<=80),"C",IF(R34>80,"D")))) -> B | AV34: T | AW34: =BV34/BW34 -> #DIV/0!
A35: 34 | B35: Pau | C35: Nouvelle Aquitaine | D35: Camp d'unité Ainés | F35: 43306 | G35: 43327 | H35: 0 | I35: 0 | J35: 0 | K35: 0 | L35: 0 | M35: 0 | N35: 5 | O35: 2 | P35: 0 | Q35: 0 | R35: =H35+J35+L35+N35+P35 -> 5 | S35: =I35+K35+M35+O35+Q35 -> 2 | T35: =S35/R35 -> 0.4 | U35: =R35+S35 -> 7 | AB35: -1 | AF35: Itinérant | AH35: Serbie Croatie | AJ35: Serbian Scout Jamborée à Ada Ciganlija près de Belgrade du 27/07/2018 au 5/08/2018 puis en Croatie | AK35: ETRANGER | AL35: CHAMPIER Daniel | AM35: daniel.champier@univ-pau.fr | AN35: 628051985 | AO35: LASPLACES Claire | AP35: 07/08 | AS35: G | AT35: =IF(D35="Camp d'unité Ainés","CUA",IF(D35="camp d'unité éclés","CUE",IF(D35="Camp d'unité louveteaux","CULO",IF(D35="Camp d'unité lutins","CULI",IF(D35="Camp de groupe","CG",IF(D35="Camp régional","CR",IF(D35="Camp de regroupement","CGG",IF(D35="Camp de regroupement d'unité Ainés","CRGUA",IF(D35="Camp de regroupement d'unité éclés","CRGUE",IF(D35="Camp de regroupement d'unité louveteaux","CRGULO",IF(D35="Camp de regroupement d'unité lutins","CRGULI",IF(D35="Camp inter groupe","CIG",IF(D35="Séjours adaptés mineurs","SAM",IF(D35="Séjours adaptés adultes","SAA",IF(D35="Séjours ouverts","SOU",IF(D35="Camp régional ouvert","RO")))))))))))))))) -> CUA | AU35: =IF(R35<=20,"A",IF(AND(R35>=21,R35<=50),"B",IF(AND(R35>=51,R35<=80),"C",IF(R35>80,"D")))) -> A | AV35: T | AW35: =BV35/BW35 -> #DIV/0!
A36: 35 | B36: Sud Cevennes | C36: Languedoc Roussillon | D36: Camp de groupe | F36: 43290 | G36: 43307 | H36: 1 | I36: 0 | J36: 7 | K36: 2 | L36: 16 | M36: 2 | N36: 0 | O36: 0 | P36: 0 | Q36: 2 | R36: =H36+J36+L36+N36+P36 -> 24 | S36: =I36+K36+M36+O36+Q36 -> 6 | T36: =S36/R36 -> 0.25 | U36: =R36+S36 -> 30 | V36: 1 | W36: 0 | X36: -3 | Y36: -1 | Z36: 1 | AA36: 0 | AB36: 0 | AC36: 0 | AD36: 0 | AF36: Camp fixe sous tente sans appui en dur | AG36: Conqueyrac | AJ36: Accueil Montfortain la Gardiolle 30170 CONQUEYRAC | AK36: EXT | AL36: BORDESSOULLES Alain | AM36: alainsud7.eedf@orange.fr | AN36: 686645267 | AO36: BORDESSOULLES Alain | AP36: 07 | AQ36: 30 | AR36: Languedoc Roussillon | AS36: G | AT36: =IF(D36="Camp d'unité Ainés","CUA",IF(D36="camp d'unité éclés","CUE",IF(D36="Camp d'unité louveteaux","CULO",IF(D36="Camp d'unité lutins","CULI",IF(D36="Camp de groupe","CG",IF(D36="Camp régional","CR",IF(D36="Camp de regroupement","CGG",IF(D36="Camp de regroupement d'unité Ainés","CRGUA",IF(D36="Camp de regroupement d'unité éclés","CRGUE",IF(D36="Camp de regroupement d'unité louveteaux","CRGULO",IF(D36="Camp de regroupement d'unité lutins","CRGULI",IF(D36="Camp inter groupe","CIG",IF(D36="Séjours adaptés mineurs","SAM",IF(D36="Séjours adaptés adultes","SAA",IF(D36="Séjours ouverts","SOU",IF(D36="Camp régional ouvert","RO")))))))))))))))) -> CG | AU36: =IF(R36<=20,"A",IF(AND(R36>=21,R36<=50),"B",IF(AND(R36>=51,R36<=80),"C",IF(R36>80,"D")))) -> B | AV36: T | AW36: =BV36/BW36 -> #DIV/0!
A37: 36 | B37: Golbey | C37: Grand Est | D37: Camp de groupe | F37: 43289 | G37: 43309 | H37: 2 | I37: 1 | J37: 3 | K37: 1 | L37: 5 | M37: 1 | N37: 3 | O37: 1 | P37: 0 | Q37: 0 | R37: =H37+J37+L37+N37+P37 -> 13 | S37: =I37+K37+M37+O37+Q37 -> 4 | T37: =S37/R37 -> 0.30769231 | U37: =R37+S37 -> 17 | Z37: -2 | AE37: -1 | AF37: Camp fixe sous tente avec appui en dur | AG37: Verrières | AJ37: 12131 | AK37: CPNB | AL37: HEURTAUT Mélanie | AM37: mel.heurtaut@gmail.com | AN37: 767944409 | AO37: DURPOIX Alain | AP37: 07 | AQ37: 12 | AR37: Midi Pyrénées | AS37: G | AT37: =IF(D37="Camp d'unité Ainés","CUA",IF(D37="camp d'unité éclés","CUE",IF(D37="Camp d'unité louveteaux","CULO",IF(D37="Camp d'unité lutins","CULI",IF(D37="Camp de groupe","CG",IF(D37="Camp régional","CR",IF(D37="Camp de regroupement","CGG",IF(D37="Camp de regroupement d'unité Ainés","CRGUA",IF(D37="Camp de regroupement d'unité éclés","CRGUE",IF(D37="Camp de regroupement d'unité louveteaux","CRGULO",IF(D37="Camp de regroupement d'unité lutins","CRGULI",IF(D37="Camp inter groupe","CIG",IF(D37="Séjours adaptés mineurs","SAM",IF(D37="Séjours adaptés adultes","SAA",IF(D37="Séjours ouverts","SOU",IF(D37="Camp régional ouvert","RO")))))))))))))))) -> CG | AU37: =IF(R37<=20,"A",IF(AND(R37>=21,R37<=50),"B",IF(AND(R37>=51,R37<=80),"C",IF(R37>80,"D")))) -> A | AV37: T | AW37: =BV37/BW37 -> #DIV/0!
A38: 37 | B38: Marseille II | C38: PAM | D38: Camp de groupe | F38: 43288 | G38: 43309 | H38: 12 | I38: 4 | J38: 18 | K38: 4 | L38: 16 | M38: 4 | N38: 11 | O38: 2 | P38: 0 | Q38: 8 | R38: =H38+J38+L38+N38+P38 -> 57 | S38: =I38+K38+M38+O38+Q38 -> 22 | T38: =S38/R38 -> 0.38596491 | U38: =R38+S38 -> 79 | V38: -3 | X38: -2 | Z38: -5 | AA38: -1 | AB38: -1 | AE38: 2 | AF38: Camp fixe sous tente sans appui en dur | AG38: Montbolo | AJ38: Scouts et guide de france Can et Mire 66110 MONTBOLO | AK38: SGDF | AL38: ORGANNI Florent | AM38: florent.org@hotmail.fr | AN38: 649520510 | AO38: MAUDUIT Jehanne | AP38: 07 | AQ38: 66 | AR38: Languedoc Roussillon | AS38: G | AT38: =IF(D38="Camp d'unité Ainés","CUA",IF(D38="camp d'unité éclés","CUE",IF(D38="Camp d'unité louveteaux","CULO",IF(D38="Camp d'unité lutins","CULI",IF(D38="Camp de groupe","CG",IF(D38="Camp régional","CR",IF(D38="Camp de regroupement","CGG",IF(D38="Camp de regroupement d'unité Ainés","CRGUA",IF(D38="Camp de regroupement d'unité éclés","CRGUE",IF(D38="Camp de regroupement d'unité louveteaux","CRGULO",IF(D38="Camp de regroupement d'unité lutins","CRGULI",IF(D38="Camp inter groupe","CIG",IF(D38="Séjours adaptés mineurs","SAM",IF(D38="Séjours adaptés adultes","SAA",IF(D38="Séjours ouverts","SOU",IF(D38="Camp régional ouvert","RO")))))))))))))))) -> CG | AU38: =IF(R38<=20,"A",IF(AND(R38>=21,R38<=50),"B",IF(AND(R38>=51,R38<=80),"C",IF(R38>80,"D")))) -> C | AV38: T | AW38: =BV38/BW38 -> #DIV/0!
A39: 38 | B39: Montredon Labessonnié | C39: Midi Pyrénées | D39: Camp d'unité éclés | F39: 43313 | G39: 43322 | H39: 0 | I39: 0 | J39: 0 | K39: 0 | L39: 5 | M39: 1 | N39: 2 | O39: 1 | P39: 0 | Q39: 0 | R39: =H39+J39+L39+N39+P39 -> 7 | S39: =I39+K39+M39+O39+Q39 -> 2 | T39: =S39/R39 -> 0.28571429 | U39: =R39+S39 -> 9 | Z39: -3 | AA39: -3 | AB39: 2 | AC39: 1 | AF39: Camp fixe sous tente sans appui en dur | AG39: Itinérant | AJ39: itinérant (12) | AK39: ITINERANT | AL39: MARQUES Mélanie | AM39: melanie.marques81@laposte.net | AN39: 633393908 | AO39: DUZES Christelle | AP39: 08 | AS39: G | AT39: =IF(D39="Camp d'unité Ainés","CUA",IF(D39="camp d'unité éclés","CUE",IF(D39="Camp d'unité louveteaux","CULO",IF(D39="Camp d'unité lutins","CULI",IF(D39="Camp de groupe","CG",IF(D39="Camp régional","CR",IF(D39="Camp de regroupement","CGG",IF(D39="Camp de regroupement d'unité Ainés","CRGUA",IF(D39="Camp de regroupement d'unité éclés","CRGUE",IF(D39="Camp de regroupement d'unité louveteaux","CRGULO",IF(D39="Camp de regroupement d'unité lutins","CRGULI",IF(D39="Camp inter groupe","CIG",IF(D39="Séjours adaptés mineurs","SAM",IF(D39="Séjours adaptés adultes","SAA",IF(D39="Séjours ouverts","SOU",IF(D39="Camp régional ouvert","RO")))))))))))))))) -> CUE | AU39: =IF(R39<=20,"A",IF(AND(R39>=21,R39<=50),"B",IF(AND(R39>=51,R39<=80),"C",IF(R39>80,"D")))) -> A | AV39: T | AW39: =BV39/BW39 -> #DIV/0!
A40: 39 | B40: Castres | C40: Midi Pyrénées | D40: Camp de groupe | F40: 43290 | G40: 43310 | H40: 0 | I40: 0 | J40: 12 | K40: 5 | L40: 39 | M40: 7 | N40: 0 | O40: 0 | P40: 0 | Q40: 0 | R40: =H40+J40+L40+N40+P40 -> 51 | S40: =I40+K40+M40+O40+Q40 -> 12 | T40: =S40/R40 -> 0.23529412 | U40: =R40+S40 -> 63 | X40: -1 | Z40: -1 | AF40: Camp fixe sous tente avec appui en dur | AG40: Viscomtat | AJ40: 63463 | AK40: CPN | AL40: COUTAREL Germain | AM40: germain.coutarel@hotmail.fr | AN40: 678036467 | AO40: PILLARD Christian | AP40: 07 | AQ40: 63 | AR40: Auvergne | AS40: G | AT40: =IF(D40="Camp d'unité Ainés","CUA",IF(D40="camp d'unité éclés","CUE",IF(D40="Camp d'unité louveteaux","CULO",IF(D40="Camp d'unité lutins","CULI",IF(D40="Camp de groupe","CG",IF(D40="Camp régional","CR",IF(D40="Camp de regroupement","CGG",IF(D40="Camp de regroupement d'unité Ainés","CRGUA",IF(D40="Camp de regroupement d'unité éclés","CRGUE",IF(D40="Camp de regroupement d'unité louveteaux","CRGULO",IF(D40="Camp de regroupement d'unité lutins","CRGULI",IF(D40="Camp inter groupe","CIG",IF(D40="Séjours adaptés mineurs","SAM",IF(D40="Séjours adaptés adultes","SAA",IF(D40="Séjours ouverts","SOU",IF(D40="Camp régional ouvert","RO")))))))))))))))) -> CG | AU40: =IF(R40<=20,"A",IF(AND(R40>=21,R40<=50),"B",IF(AND(R40>=51,R40<=80),"C",IF(R40>80,"D")))) -> C | AV40: T | AW40: =BV40/BW40 -> #DIV/0!
...

Sheet BAFA18
A1: PV BAFA 2018 | C1: en attente de PV recevable | E1: PV Recevable | G1: en attente du vrai PV déclaré | H1: Annulé | I1: mois à traiter pour la synthèse
A2: Réf | B2: N°session | C2: Session Général-Appro-Qualification | D2: Type d'hébergement Internat-Externat | E2: Date | F2: Département | G2: Adresse de session | H2: Territoire | I2: Région | J2: Civilité | K2: Nom du directeur | L2: Qualification du directeur | M2: Nombre de formateur | N2: Nom des Formateurs | O2: Garçon | P2: Fille | Q2: Qualification des formateurs | R2: Nombre de stagiaires | S2: Garçon | T2: Fille | U2: nombre d'avis satisfaisante | V2: Nombre d'avis non satisfaisante | W2: Nombre d'avis en tant qu'appro | X2: Nombre d'avis en Qualification
A3: 1 | B3: 18031BAFA72161 | C3: Approfondissement | D3: Internat | E3: 26/02/2018 au 03/03/2018 | F3: 31 | G3: Domaine dui T 86 route du chapitre 31130 Balma | H3: 4 | I3: Midi Pyrénées | J3: Madame | K3: Colzy Claire | L3: BAFD | M3: 3 | N3: Colzy Jean Follet Pierre Assens Aurélie | O3: 2 | P3: 1 | Q3: BAFA BAFA BAFA | R3: 13 | S3: 5 | T3: 8 | U3: 13 | V3: 0 | W3: 13 | X3: 0
A4: 2 | B4: 18011BAFA72155 | C4: Générale | D4: Internat | E4: 18/02/2018 au 25/02/2018 | F4: 11 | G4: Leap Emile de Rodat 8 boulevard Gérard de Pins 11170 Pezens | H4: 4 | I4: Midi Pyrénées | J4: Monsieur | K4: Birée Florian | L4: BAFD | M4: 3 | N4: Cotonat Marion Jourdain Maxime Zimpfer Claire Line | O4: 1 | P4: 2 | Q4: BP JEPS UCC direction CVL BAFA BAFA | R4: 15 | S4: 6 | T4: 9 | U4: 14 | V4: 1 | W4: 0 | X4: 0
A5: 3 | B5: 18032BAFA72156 | C5: Générale | D5: Internat | E5: 24/02/2018 au 03/03/2018 | F5: 32 | G5: Lycée des métiers le Carros 1 bis rue Darwin BP 60529 32021 Auch | H5: 4 | I5: Midi Pyrénées | J5: Madame | K5: Oliveros Fanny | L5: BAFD | M5: 3 | N5: BOTTON Aurélien Gonin Camille Tilhou Bérénice | O5: 1 | P5: 2 | Q5: BAFD BP JEPS UCC direction CVL BAFA | R5: 17 | S5: 5 | T5: 12 | U5: 17 | V5: 0 | W5: 0 | X5: 0
A6: 4 | B6: 18063BAFA71367 | C6: Générale | D6: Internat | E6: 10/02/2018 au 17/02/2018 | F6: 63 | G6: 63463 | H6: 5 | I6: Auvergne | J6: Monsieur | K6: Louis Jonathan | L6: BP JEPS spécialisé LTP | M6: 1 | N6: Banda Alexandre | O6: 1 | P6: 0 | Q6: BP JEPS | R6: 12 | S6: 8 | T6: 4 | U6: 12 | V6: 0 | W6: 0 | X6: 0
A7: 5 | B7: 18006BAFA71958 | C7: Générale | D7: Internat | E7: 25/02/2018 au 04/03/2018 | F7: 06 | G7: Les Courmettes route des Courmettes 06140 Tourrettes sur Loup | H7: 6 | I7: PAM | J7: Madame | K7: Lukovic Snejana | L7: BAFD | M7: 3 | N7: Organini Florent Chatel Léa Frison Julie | O7: 1 | P7: 2 | Q7: BAFA BAFA BAFA | R7: 20 | S7: 18 | T7: 2 | U7: 20 | V7: 0 | W7: 0 | X7: 0
